Workbook
Name Projeto: '210814 - Regionalização'!$AR$5
Name Projeto: '210815 - Regula Mais'!$AR$5
Name Projeto: '210816 - Saude'!$AR$5
Name Projeto: '210818 - Rede'!$AR$5
Name Projeto: 'MATRIZ - Relat Desp_CLT'!$AR$6
Name Projeto: 'MATRIZ - Relat Despesas'!$AR$6
Name Projeto: #REF!

Sheet Premissas
A10: PREMISSAS DE REEMBOLSO
A12: Dados do Solicitante
A13: Nome da PJ ou do funcionário CLT
A14: Tipo: BP ou CNPJ
A15: Projeto: selecionar o Centro de Custo do projeto
A16: EAP: indicar qual o código e descrição a despesa está relacionada na EAP
A17: Atividade: descrever o motivo da viagem - Ex. "Reunião de Alinhamento Secretário de Saúde - SES/PR"
A18: Período: indicar o período da viagem ou atividade
A19: Indicar se a despesa refere-se a: adiantamento de viagem/ Reembolso/ Cartão Corporativo
A21: Dados Bancários
A22: Inserir dados bancários da PJ quando se tratar de empresa e da PF quando se tratar de funcionário
A24: Documentos - Comprovação
... A51: Caberá ao PJ o envio de forma conjunta a este formulário a NOTA DE DÉBITO

Sheet Bases - Cadastro
A2: =B2&C2
A3: Contatenado | B3: CC | C3: Descrição | E3: TIPO | F3: TIPO
A4: =B4&C4 -> 210807 Escritório PROADI SUS | B4: 210807 | C4: Escritório PROADI SUS | E4: BP | F4: BP
A5: =B5&C5 -> 210809 PROADI SUS | B5: 210809 | C5: PROADI SUS | E5: CNPJ | F5: CNPJ
A6: =B6&C6 -> 490307 Sustentabilidade BP Mirante | B6: 490307 | C6: Sustentabilidade BP Mirante
A7: =B7&C7 -> 390206 Sustentabilidade | B7: 390206 | C7: Sustentabilidade
A8: =B8&C8 -> 210404 Filantropia | B8: 210404 | C8: Filantropia
A9: =B9&C9 -> 210813 Projetos Sociais BP | B9: 210813 | C9: Projetos Sociais BP
A10: 210833 PROADI Projeto Rede CONASEMS/ COSEMS | B10: 210833 | C10: PROADI Projeto Rede CONASEMS/ COSEMS
A11: 210834 PROADI Projeto Impacto MR Seguimento | B11: 210834 | C11: PROADI Projeto Impacto MR Seguimento
A12: 210835 PROADI Projeto Impacto MR Intervenção | B12: 210835 | C12: PROADI Projeto Impacto MR Intervenção
A13: 210836 PROADI Projeto Planificação 2024/2026 | B13: 210836 | C13: PROADI Projeto Planificação 2024/2026
A14: 210837 PROADI Projeto Tele Nordeste 2024/2026 | B14: 210837 | C14: PROADI Projeto Tele Nordeste 2024/2026
A15: 210838 PROADI Projeto Educa DTN – VE 2024/2026 | B15: 210838 | C15: PROADI Projeto Educa DTN – VE 2024/2026
A16: 210839 PROADI Projeto Saúde Integral da Mulher | B16: 210839 | C16: PROADI Projeto Saúde Integral da Mulher
A17: 210840 PROADI Projeto QualiGuia APS | B17: 210840 | C17: PROADI Projeto QualiGuia APS
A18: 210841 PROADI Projeto Proven Dia 2024/2026 | B18: 210841 | C18: PROADI Projeto Proven Dia 2024/2026
A19: 210842 PROADI Projeto Lean nas Emergências Continuidade | B19: 210842 | C19: PROADI Projeto Lean nas Emergências Continuidade
A20: 210843 PROADI Projeto Saúde em Nossas Mãos Continuidade | B20: 210843 | C20: PROADI Projeto Saúde em Nossas Mãos Continuidade
A21: 210844 PROADI Projeto Capacitação BLS Continuidade | B21: 210844 | C21: PROADI Projeto Capacitação BLS Continuidade
... A36: 210863 - Proadi - Projeto Aprimora Sus | B36: 210863 | C36: PROADI Projeto Aprimora Sus 2024/2026
A37: Concatenado - CONTA CONTÁBIL | B37: COD CONTA CONTABIL | C37: DESCRIÇÃO | D37: Codigo Material - Concatenado (TASY) | E37: COD MATERIAL | F37: DESCRIÇÃO MATERIAL (tasy) | G37: Observação
A38: PR50050001 - Material uso e consumo PROADI SUS | B38: =MID(A38,1,11) -> PR50050001 | C38: =MID(A38,15,39) -> Material uso e consumo PROADI SUS | D38: 263020 Reembolso de Material de Uso e Consumo PROADI SUS | E38: =MID(D38,1,6) -> 263020 | F38: =MID(D38,8,49) -> Reembolso de Material de Uso e Consumo PROADI SUS | G38: Compras de emergência durante viagem - limitado à R$ 100,00 + aprovação coordenador
A39: PR50060002 - Refeições e Lanches PROADI SUS | B39: =MID(A39,1,11) -> PR50060002 | C39: =MID(A39,15,39) -> Refeições e Lanches PROADI SUS | D39: 263018 Reembolso de Refeições e Lanches PROADI SUS | E39: =MID(D39,1,6) -> 263018 | F39: =MID(D39,8,43) -> Reembolso de Refeições e Lanches PROADI SUS | G39: Almoço, jantar, água
A40: PR50060003 - Condução e Transporte PROADI SUS | B40: =MID(A40,1,11) -> PR50060003 | C40: =MID(A40,15,39) -> Condução e Transporte PROADI SUS | D40: 263962 Reembolso de Condução e Transporte PROADI SUS | E40: =MID(D40,1,6) -> 263962 | F40: =MID(D40,8,45) -> Reembolso de Condução e Transporte PROADI SUS | G40: Taxi, Uber, 99, estacionamento, pedágio, combustível veículo alugado, rodoviário (ônibus de viagem)
A41: PR50060004 - Passagens Aereas PROADI SUS | B41: =MID(A41,1,11) -> PR50060004 | C41: =MID(A41,15,39) -> Passagens Aereas PROADI SUS | D41: 263021 Reembolso de Passagem Aérea PROADI SUS | E41: =MID(D41,1,6) -> 263021 | F41: =MID(D41,8,38) -> Reembolso de Passagem Aérea PROADI SUS | G41: Exceção por omissão ou indisponibilidade pela agência de viagens contratada
A42: PR50060005 - Hospedagem PROADI SUS | B42: =MID(A42,1,11) -> PR50060005 | C42: =MID(A42,15,39) -> Hospedagem PROADI SUS | D42: 263022 Reembolso de Hospedagem PROADI SUS | E42: =MID(D42,1,6) -> 263022 | F42: =MID(D42,8,34) -> Reembolso de Hospedagem PROADI SUS | G42: Diárias de hotéis exceção por omissão ou indisponibilidade da agência de viagens
A43: PR50060006 - Taxas de Viagens, Eventos e Congressos PROADI SUS | B43: =MID(A43,1,11) -> PR50060006 | C43: =MID(A43,15,49) -> Taxas de Viagens, Eventos e Congressos PROADI SUS | D43: 263023 Reembolso de Inscrições de Eventos PROADI SUS | E43: =MID(D43,1,6) -> 263023 | F43: =MID(D43,8,45) -> Reembolso de Inscrições de Eventos PROADI SUS | G43: Congressos
A44: PR50090003 - Custas de cartório PROADI SUS | B44: =MID(A44,1,11) -> PR50090003 | C44: =MID(A44,15,39) -> Custas de cartório PROADI SUS | D44: 263017 Reembolso de Cartório PROADI SUS | E44: =MID(D44,1,6) -> 263017 | F44: =MID(D44,8,32) -> Reembolso de Cartório PROADI SUS | G44: Autenticações, reconhecimento de firma
A45: PR50090005 - Correios e Malotes PROADI SUS | B45: =MID(A45,1,11) -> PR50090005 | C45: =MID(A45,15,39) -> Correios e Malotes PROADI SUS | D45: 263016 Reembolso de Correios PROADI SUS | E45: =MID(D45,1,6) -> 263016 | F45: =MID(D45,8,32) -> Reembolso de Correios PROADI SUS | G45: Postagens em geral em agência de Correios
A46: PR50090011 - Revelações, Cópias, Impressões e Gráfica PROADI SUS | B46: =MID(A46,1,11) -> PR50090011 | C46: =MID(A46,15,51) -> Revelações, Cópias, Impressões e Gráfica PROADI SUS | D46: 263019 Reembolso de Revelações, Cópias e Gráfica PROADI SUS | E46: =MID(D46,1,6) -> 263019 | F46: =MID(D46,8,52) -> Reembolso de Revelações, Cópias e Gráfica PROADI SUS | G46: cópias, xerox, reproduções, encadernações, banners - deve ser utilizado como exceção durante viagem
A55: Contatenado | B55: Código | C55: Banco
A56: 1 - Banco do Brasil S.A. | B56: 1 | C56: Banco do Brasil S.A.
A57: 33 - Banco Santander (Brasil) S.A. | B57: 33 | C57: Banco Santander (Brasil) S.A.
A58: 237 - Banco Bradesco S.A. | B58: 237 | C58: Banco Santander (Brasil) S.A.
A59: 260 - Nu Pagamentos S.A (Nubank) | B59: 260 | C59: Nu Pagamentos S.A (Nubank)
A60: 341 - Itaú Unibanco S.A. | B60: 341 | C60: Itaú Unibanco S.A.
A61: 745 - Banco Citibank S.A. | B61: 745 | C61: Banco Citibank S.A.
A62: 3 - Banco da Amazônia S.A. | B62: 3 | C62: Banco da Amazônia S.A.
A63: 4 - Banco do Nordeste do Brasil S.A. | B63: 4 | C63: Banco do Nordeste do Brasil S.A.
...

Sheet MATRIZ - Relat Desp_CLT
B2: RELATÓRIO DESPESAS - PROADI SUS
B6: Solicitante: | Z6: BP | AJ6: Projeto: | AN6: 210814 PROADI - Projeto Regionalização
B8: Atividade:
B10: Período: | N10: à | AG10: EAP - Atividade
B12: Local | Região: | H12: Brasília/DF
D15: Caixa | BP | J15: Adiantamento de viagem | T15: Reembolso Conta Corrente | AI15: Cartão de Credito Corporativo
C18: DADOS BANCÁRIOS: | S18: (Caso Banco não esteja cadastrado)
B20: Número / Banco | U20: Agência: | AH20: - | AN20: Conta Corrente: | AS20: -
B22: GASTOS REALIZADOS | AN22: Reembolsos
B23: Valor Adiantado | Q23: Valor utilizado | AA23: Saldo | AN23: Valor
B24: 0 | Q24: =AU80 -> 479.71 | AA24: 0 | AN24: =AU80 -> 479.71
B26: Comprovante de Despesas
B28: DATA | G28: CENTRO DE CUSTO | L28: PROJETO | Q28: Nº NF | U28: Fornecedor | AA28: Descrição | AO28: CLASSIFICAÇÃO | AR28: CÓD. | AU28: VALOR R$
AO29: DESPESA | AR29: DESP.
G30: 210816 | L30: =IF(G30="","",VLOOKUP($AN$6,'Bases - Cadastro'!A:C,3,0)) -> #N/A | Q30: 60675 | U30: FBWM COMERCIO DE BEBIDAS E ALIMENTOS LTDA | AA30: Refeição: Jantar | AO30: Refeições e Lanches PROADI SUS | AR30: =_xlfn.IFNA(VLOOKUP(AO30,'Bases - Cadastro'!$A$37:$B$62,2,0),"") | AU30: 49 | BB30: Excluido gorjeta, bebida alcoolica, couvert artístico
G31: 210816 | L31: =IF(G31="","",VLOOKUP($AN$6,'Bases - Cadastro'!A:C,3,0)) -> #N/A | Q31: 60615 | U31: FBWM COMERCIO DE BEBIDAS E ALIMENTOS LTDA | AA31: Refeição: Jantar | AO31: Refeições e Lanches PROADI SUS | AR31: =_xlfn.IFNA(VLOOKUP(AO31,'Bases - Cadastro'!$A$37:$B$62,2,0),"") | AU31: 110 | BB31: Valor limite dia
G32: 210816 | L32: =IF(G32="","",VLOOKUP($AN$6,'Bases - Cadastro'!A:C,3,0)) -> #N/A | Q32: - | U32: - | AA32: Taxi: Residência-Aeroporto | AO32: Refeições e Lanches PROADI SUS | AR32: =_xlfn.IFNA(VLOOKUP(AO32,'Bases - Cadastro'!$A$37:$B$62,2,0),"") | AU32: 47
G33: 210816 | L33: =IF(G33="","",VLOOKUP($AN$6,'Bases - Cadastro'!A:C,3,0)) -> #N/A | Q33: - | U33: - | AA33: Taxi: Aeroporto-Hotel | AO33: Refeições e Lanches PROADI SUS | AR33: =_xlfn.IFNA(VLOOKUP(AO33,'Bases - Cadastro'!$A$37:$B$62,2,0),"") | AU33: 44.77
G34: 210816 | L34: =IF(G34="","",VLOOKUP($AN$6,'Bases - Cadastro'!A:C,3,0)) -> #N/A | Q34: - | U34: - | AA34: Taxi: Hotel-Aeroporto | AO34: Refeições e Lanches PROADI SUS | AR34: =_xlfn.IFNA(VLOOKUP(AO34,'Bases - Cadastro'!$A$37:$B$62,2,0),"") | AU34: 50
G35: 210816 | L35: =IF(G35="","",VLOOKUP($AN$6,'Bases - Cadastro'!A:C,3,0)) -> #N/A | Q35: - | U35: GUARUCOOP | AA35: Taxi: Aeroporto-Residência | AO35: Refeições e Lanches PROADI SUS | AR35: =_xlfn.IFNA(VLOOKUP(AO35,'Bases - Cadastro'!$A$37:$B$62,2,0),"") | AU35: 178.94
L36: =IF(G36="","",VLOOKUP($AN$6,'Bases - Cadastro'!A:C,3,0)) | AR36: =_xlfn.IFNA(VLOOKUP(AO36,'Bases - Cadastro'!$A$37:$B$62,2,0),"")
L37: =IF(G37="","",VLOOKUP($AN$6,'Bases - Cadastro'!A:C,3,0)) | AR37: =_xlfn.IFNA(VLOOKUP(AO37,'Bases - Cadastro'!$A$37:$B$62,2,0),"")
L38: =IF(G38="","",VLOOKUP($AN$6,'Bases - Cadastro'!A:C,3,0)) | AR38: =_xlfn.IFNA(VLOOKUP(AO38,'Bases - Cadastro'!$A$37:$B$62,2,0),"")
L39: =IF(G39="","",VLOOKUP($AN$6,'Bases - Cadastro'!A:C,3,0)) | AR39: =_xlfn.IFNA(VLOOKUP(AO39,'Bases - Cadastro'!$A$37:$B$62,2,0),"")
L40: =IF(G40="","",VLOOKUP($AN$6,'Bases - Cadastro'!A:C,3,0)) | AR40: =_xlfn.IFNA(VLOOKUP(AO40,'Bases - Cadastro'!$A$37:$B$62,2,0),"")
L41: =IF(G41="","",VLOOKUP($AN$6,'Bases - Cadastro'!A:C,3,0)) | AR41: =_xlfn.IFNA(VLOOKUP(AO41,'Bases - Cadastro'!$A$37:$B$62,2,0),"")
L42: =IF(G42="","",VLOOKUP($AN$6,'Bases - Cadastro'!A:C,3,0)) | AR42: =_xlfn.IFNA(VLOOKUP(AO42,'Bases - Cadastro'!$A$37:$B$62,2,0),"")
L43: =IF(G43="","",VLOOKUP($AN$6,'Bases - Cadastro'!A:C,3,0)) | AR43: =_xlfn.IFNA(VLOOKUP(AO43,'Bases - Cadastro'!$A$37:$B$62,2,0),"")
L44: =IF(G44="","",VLOOKUP($AN$6,'Bases - Cadastro'!A:C,3,0)) | AR44: =_xlfn.IFNA(VLOOKUP(AO44,'Bases - Cadastro'!$A$37:$B$62,2,0),"")
L45: =IF(G45="","",VLOOKUP($AN$6,'Bases - Cadastro'!A:C,3,0)) | AR45: =_xlfn.IFNA(VLOOKUP(AO45,'Bases - Cadastro'!$A$37:$B$62,2,0),"")
L46: =IF(G46="","",VLOOKUP($AN$6,'Bases - Cadastro'!A:C,3,0)) | AR46: =_xlfn.IFNA(VLOOKUP(AO46,'Bases - Cadastro'!$A$37:$B$62,2,0),"")
L47: =IF(G47="","",VLOOKUP($AN$6,'Bases - Cadastro'!A:C,3,0)) | AR47: =_xlfn.IFNA(VLOOKUP(AO47,'Bases - Cadastro'!$A$37:$B$62,2,0),"")
... L79: =IF(G79="","",VLOOKUP($AN$6,'Bases - Cadastro'!A:C,3,0)) | AR79: =_xlfn.IFNA(VLOOKUP(AO79,'Bases - Cadastro'!$A$37:$B$62,2,0),"")
B80: TOTAL | AU80: =SUM(AU30:BA79) -> 479.71
C82: Solicitante | U82: Aprovador
C83: DATA | H83: Nome | U83: DATA | W83: Nome
C84: =TODAY() -> 46064 | U84: =TODAY() -> 46064
D86: Resumo Contábil | P86: Conta Contábil | V86: =SUM(V87:Z98) -> 0 | AD86: OBSERVAÇÕES
B87: 1 | D87: ='Bases - Cadastro'!A38 -> PR50050001 - Material uso e consumo PROADI SUS | P87: ='Bases - Cadastro'!D38 -> 263020 Reembolso de Material de Uso e Consumo PROADI SUS | V87: =SUMIF($AR$30:$AT$79,P87,$AU$30:$BA$79) -> 0
B88: 2 | D88: ='Bases - Cadastro'!A39 -> PR50060002 - Refeições e Lanches PROADI SUS | P88: ='Bases - Cadastro'!D39 -> 263018 Reembolso de Refeições e Lanches PROADI SUS | V88: =SUMIF($AR$30:$AT$79,P88,$AU$30:$BA$79) -> 0
...

Sheet MATRIZ - Relat Despesas
B2: RELATÓRIO DESPESAS - PROADI SUS
B6: Solicitante: | Z6: BP | AJ6: Projeto: | AN6: 210863 - Proadi - Projeto Aprimora Sus
B8: Atividade:
B10: Período: | N10: a | AG10: EAP - Atividade
B12: Local | Região: | H12: São Paulo
D15: Caixa | BP | J15: Adiantamento de viagem | T15: Reembolso Conta Corrente | AI15: Cartão de Credito Corporativo
H18: DADOS BANCÁRIOS: | S18: (Caso Banco não esteja cadastrado)
B20: Número / Banco | I20: 33 - Banco Santander (Brasil) S.A. | U20: Agência: | AA20: 4326 | AH20: - | AO20: Conta Corrente: | AP20: 10479918 | AS20: -
B22: GASTOS REALIZADOS | AN22: Reembolsos
B23: Valor Adiantado | Q23: Valor utilizado | AA23: Saldo | AN23: Valor
Q24: =AU80 -> 0 | AA24: =B24-Q24 -> 0 | AN24: =IF(AA24<0,Q24-B24,IF(AA24>0,"0,0",AU80-B24)) -> 0
B26: Comprovante de Despesas
B28: DATA | G28: CENTRO DE CUSTO | L28: PROJETO | Q28: Nº NF | U28: Fornecedor | AA28: Descrição | AO28: CLASSIFICAÇÃO | AR28: CÓD. | AU28: VALOR R$
AO29: DESPESA | AR29: CONTÁBIL
G30: =IFERROR(VLOOKUP($AN$6,'Bases - Cadastro'!$A$4:$C$35,2,0),"") -> 210863 | L30: =IF($G30="","",VLOOKUP($AN$6,'Bases - Cadastro'!A:C,3,0)) -> PROADI Projeto Aprimora Sus 2024/2026
G31: =IFERROR(VLOOKUP($AN$6,'Bases - Cadastro'!$A$4:$C$35,2,0),"") -> 210863 | L31: =IF(G31="","",VLOOKUP($AN$6,'Bases - Cadastro'!A:C,3,0)) -> PROADI Projeto Aprimora Sus 2024/2026
G32: =IFERROR(VLOOKUP($AN$6,'Bases - Cadastro'!$A$4:$C$35,2,0),"") -> 210863 | L32: =IF(G32="","",VLOOKUP($AN$6,'Bases - Cadastro'!A:C,3,0)) -> PROADI Projeto Aprimora Sus 2024/2026
G33: =IFERROR(VLOOKUP($AN$6,'Bases - Cadastro'!$A$4:$C$35,2,0),"") -> 210863 | L33: =IF(G33="","",VLOOKUP($AN$6,'Bases - Cadastro'!A:C,3,0)) -> PROADI Projeto Aprimora Sus 2024/2026
G34: =IFERROR(VLOOKUP($AN$6,'Bases - Cadastro'!$A$4:$C$35,2,0),"") -> 210863 | L34: =IF(G34="","",VLOOKUP($AN$6,'Bases - Cadastro'!A:C,3,0)) -> PROADI Projeto Aprimora Sus 2024/2026
G35: =IFERROR(VLOOKUP($AN$6,'Bases - Cadastro'!$A$4:$C$35,2,0),"") -> 210863 | L35: =IF(G35="","",VLOOKUP($AN$6,'Bases - Cadastro'!A:C,3,0)) -> PROADI Projeto Aprimora Sus 2024/2026
G36: =IFERROR(VLOOKUP($AN$6,'Bases - Cadastro'!$A$4:$C$35,2,0),"") -> 210863 | L36: =IF(G36="","",VLOOKUP($AN$6,'Bases - Cadastro'!A:C,3,0)) -> PROADI Projeto Aprimora Sus 2024/2026
G37: =IFERROR(VLOOKUP($AN$6,'Bases - Cadastro'!$A$4:$C$35,2,0),"") -> 210863 | L37: =IF(G37="","",VLOOKUP($AN$6,'Bases - Cadastro'!A:C,3,0)) -> PROADI Projeto Aprimora Sus 2024/2026
G38: =IFERROR(VLOOKUP($AN$6,'Bases - Cadastro'!$A$4:$C$35,2,0),"") -> 210863 | L38: =IF(G38="","",VLOOKUP($AN$6,'Bases - Cadastro'!A:C,3,0)) -> PROADI Projeto Aprimora Sus 2024/2026
G39: =IFERROR(VLOOKUP($AN$6,'Bases - Cadastro'!$A$4:$C$35,2,0),"") -> 210863 | L39: =IF(G39="","",VLOOKUP($AN$6,'Bases - Cadastro'!A:C,3,0)) -> PROADI Projeto Aprimora Sus 2024/2026
G40: =IFERROR(VLOOKUP($AN$6,'Bases - Cadastro'!$A$4:$C$35,2,0),"") -> 210863 | L40: =IF(G40="","",VLOOKUP($AN$6,'Bases - Cadastro'!A:C,3,0)) -> PROADI Projeto Aprimora Sus 2024/2026
G41: =IFERROR(VLOOKUP($AN$6,'Bases - Cadastro'!$A$4:$C$35,2,0),"") -> 210863 | L41: =IF(G41="","",VLOOKUP($AN$6,'Bases - Cadastro'!A:C,3,0)) -> PROADI Projeto Aprimora Sus 2024/2026
G42: =IFERROR(VLOOKUP($AN$6,'Bases - Cadastro'!$A$4:$C$35,2,0),"") -> 210863 | L42: =IF(G42="","",VLOOKUP($AN$6,'Bases - Cadastro'!A:C,3,0)) -> PROADI Projeto Aprimora Sus 2024/2026
... G63: =IFERROR(VLOOKUP($AN$6,'Bases - Cadastro'!$A$4:$C$35,2,0),"") -> 210863 | L63: =IF(G63="","",VLOOKUP($AN$6,'Bases - Cadastro'!A:C,3,0)) -> PROADI Projeto Aprimora Sus 2024/2026
G64: =IFERROR(VLOOKUP($AN$6,'Bases - Cadastro'!$A$4:$C$35,2,0),"") -> 210863 | L64: =IF(G64="","",VLOOKUP($AN$6,'Bases - Cadastro'!A:C,3,0)) -> PROADI Projeto Aprimora Sus 2024/2026 | AR64: =IFERROR(VLOOKUP($AO64,$D$87:$U$95,13,0),"")
G65: =IFERROR(VLOOKUP($AN$6,'Bases - Cadastro'!$A$4:$C$35,2,0),"") -> 210863 | L65: =IF(G65="","",VLOOKUP($AN$6,'Bases - Cadastro'!A:C,3,0)) -> PROADI Projeto Aprimora Sus 2024/2026 | AR65: =IFERROR(VLOOKUP($AO65,$D$87:$U$95,13,0),"")
G66: =IFERROR(VLOOKUP($AN$6,'Bases - Cadastro'!$A$4:$C$35,2,0),"") -> 210863 | L66: =IF(G66="","",VLOOKUP($AN$6,'Bases - Cadastro'!A:C,3,0)) -> PROADI Projeto Aprimora Sus 2024/2026 | AR66: =IFERROR(VLOOKUP($AO66,$D$87:$U$95,13,0),"")
G67: =IFERROR(VLOOKUP($AN$6,'Bases - Cadastro'!$A$4:$C$35,2,0),"") -> 210863 | L67: =IF(G67="","",VLOOKUP($AN$6,'Bases - Cadastro'!A:C,3,0)) -> PROADI Projeto Aprimora Sus 2024/2026 | AR67: =IFERROR(VLOOKUP($AO67,$D$87:$U$95,13,0),"")
G68: =IFERROR(VLOOKUP($AN$6,'Bases - Cadastro'!$A$4:$C$35,2,0),"") -> 210863 | L68: =IF(G68="","",VLOOKUP($AN$6,'Bases - Cadastro'!A:C,3,0)) -> PROADI Projeto Aprimora Sus 2024/2026 | AR68: =IFERROR(VLOOKUP($AO68,$D$87:$U$95,13,0),"")
G69: =IFERROR(VLOOKUP($AN$6,'Bases - Cadastro'!$A$4:$C$35,2,0),"") -> 210863 | L69: =IF(G69="","",VLOOKUP($AN$6,'Bases - Cadastro'!A:C,3,0)) -> PROADI Projeto Aprimora Sus 2024/2026 | AR69: =IFERROR(VLOOKUP($AO69,$D$87:$U$95,13,0),"")
G70: =IFERROR(VLOOKUP($AN$6,'Bases - Cadastro'!$A$4:$C$35,2,0),"") -> 210863 | L70: =IF(G70="","",VLOOKUP($AN$6,'Bases - Cadastro'!A:C,3,0)) -> PROADI Projeto Aprimora Sus 2024/2026 | AR70: =IFERROR(VLOOKUP($AO70,$D$87:$U$95,13,0),"")
G71: =IFERROR(VLOOKUP($AN$6,'Bases - Cadastro'!$A$4:$C$35,2,0),"") -> 210863 | L71: =IF(G71="","",VLOOKUP($AN$6,'Bases - Cadastro'!A:C,3,0)) -> PROADI Projeto Aprimora Sus 2024/2026 | AR71: =IFERROR(VLOOKUP($AO71,$D$87:$U$95,13,0),"")
G72: =IFERROR(VLOOKUP($AN$6,'Bases - Cadastro'!$A$4:$C$35,2,0),"") -> 210863 | L72: =IF(G72="","",VLOOKUP($AN$6,'Bases - Cadastro'!A:C,3,0)) -> PROADI Projeto Aprimora Sus 2024/2026 | AR72: =IFERROR(VLOOKUP($AO72,$D$87:$U$95,13,0),"")
G73: =IFERROR(VLOOKUP($AN$6,'Bases - Cadastro'!$A$4:$C$35,2,0),"") -> 210863 | L73: =IF(G73="","",VLOOKUP($AN$6,'Bases - Cadastro'!A:C,3,0)) -> PROADI Projeto Aprimora Sus 2024/2026 | AR73: =IFERROR(VLOOKUP($AO73,$D$87:$U$95,13,0),"")
G74: =IFERROR(VLOOKUP($AN$6,'Bases - Cadastro'!$A$4:$C$35,2,0),"") -> 210863 | L74: =IF(G74="","",VLOOKUP($AN$6,'Bases - Cadastro'!A:C,3,0)) -> PROADI Projeto Aprimora Sus 2024/2026 | AR74: =IFERROR(VLOOKUP($AO74,$D$87:$U$95,13,0),"")
G75: =IFERROR(VLOOKUP($AN$6,'Bases - Cadastro'!$A$4:$C$35,2,0),"") -> 210863 | L75: =IF(G75="","",VLOOKUP($AN$6,'Bases - Cadastro'!A:C,3,0)) -> PROADI Projeto Aprimora Sus 2024/2026 | AR75: =IFERROR(VLOOKUP($AO75,$D$87:$U$95,13,0),"")
...

Sheet 210814 - Regionalização
B1: RELATÓRIO DESPESAS - PROADI SUS
B5: Solicitante: | Z5: BP | AJ5: Projeto: | AN5: ='Bases - Cadastro'!A10 -> 210833 PROADI Projeto Rede CONASEMS/ COSEMS
B7: Atividade:
B9: Período: | N9: à | AG9: EAP - Atividade
B11: Local | Região:
D14: Caixa | BP | I14: Adiantamento de viagem | S14: Reembolso Conta Corrente | AI14: Cartão de Credito Corporativo
C17: DADOS BANCÁRIOS: | S17: (Caso Banco não esteja cadastrado)
B19: Número / Banco | U19: Agência: | AH19: - | AN19: Conta Corrente: | AS19: -
B21: GASTOS REALIZADOS | AN21: Reembolsos
B22: Valor Adiantado | Q22: Valor utilizado | AA22: Saldo | AN22: Valor
B23: 0 | Q23: =AU67 -> 1384.31 | AA23: 0 | AN23: =AU67 -> 1384.31
B25: Comprovante de Despesas
B27: DATA | G27: CENTRO DE CUSTO | L27: PROJETO | Q27: Nº NF | U27: Fornecedor | AA27: Descrição | AO27: CLASSIFICAÇÃO | AR27: CÓD. | AU27: VALOR R$
AO28: DESPESA | AR28: DESP.
B29: 23/08/21 | G29: 210807 | L29: =IF(G29="","",VLOOKUP($AN$5,'Bases - Cadastro'!A:C,3,0)) -> PROADI Projeto Rede CONASEMS/ COSEMS | U29: Cia Vip | AA29: Hospedagem Hotel Melia - 23 a 26/08/21 - XXXXX | AO29: Viagens e Estadias PROADI SUS | AR29: =_xlfn.IFNA(VLOOKUP(AO29,'Bases - Cadastro'!$A$37:$B$62,2,0),"") | AU29: 1384.31
L30: =IF(G30="","",VLOOKUP($AN$5,'Bases - Cadastro'!A:C,3,0)) | AR30: =_xlfn.IFNA(VLOOKUP(AO30,'Bases - Cadastro'!$A$37:$B$62,2,0),"")
L31: =IF(G31="","",VLOOKUP($AN$5,'Bases - Cadastro'!A:C,3,0)) | AR31: =_xlfn.IFNA(VLOOKUP(AO31,'Bases - Cadastro'!$A$37:$B$62,2,0),"")
L32: =IF(G32="","",VLOOKUP($AN$5,'Bases - Cadastro'!A:C,3,0)) | AR32: =_xlfn.IFNA(VLOOKUP(AO32,'Bases - Cadastro'!$A$37:$B$62,2,0),"")
L33: =IF(G33="","",VLOOKUP($AN$5,'Bases - Cadastro'!A:C,3,0)) | AR33: =_xlfn.IFNA(VLOOKUP(AO33,'Bases - Cadastro'!$A$37:$B$62,2,0),"")
L34: =IF(G34="","",VLOOKUP($AN$5,'Bases - Cadastro'!A:C,3,0)) | AR34: =_xlfn.IFNA(VLOOKUP(AO34,'Bases - Cadastro'!$A$37:$B$62,2,0),"")
L35: =IF(G35="","",VLOOKUP($AN$5,'Bases - Cadastro'!A:C,3,0)) | AR35: =_xlfn.IFNA(VLOOKUP(AO35,'Bases - Cadastro'!$A$37:$B$62,2,0),"")
L36: =IF(G36="","",VLOOKUP($AN$5,'Bases - Cadastro'!A:C,3,0)) | AR36: =_xlfn.IFNA(VLOOKUP(AO36,'Bases - Cadastro'!$A$37:$B$62,2,0),"")
L37: =IF(G37="","",VLOOKUP($AN$5,'Bases - Cadastro'!A:C,3,0)) | AR37: =_xlfn.IFNA(VLOOKUP(AO37,'Bases - Cadastro'!$A$37:$B$62,2,0),"")
L38: =IF(G38="","",VLOOKUP($AN$5,'Bases - Cadastro'!A:C,3,0)) | AR38: =_xlfn.IFNA(VLOOKUP(AO38,'Bases - Cadastro'!$A$37:$B$62,2,0),"")
L39: =IF(G39="","",VLOOKUP($AN$5,'Bases - Cadastro'!A:C,3,0)) | AR39: =_xlfn.IFNA(VLOOKUP(AO39,'Bases - Cadastro'!$A$37:$B$62,2,0),"")
L40: =IF(G40="","",VLOOKUP($AN$5,'Bases - Cadastro'!A:C,3,0)) | AR40: =_xlfn.IFNA(VLOOKUP(AO40,'Bases - Cadastro'!$A$37:$B$62,2,0),"")
L41: =IF(G41="","",VLOOKUP($AN$5,'Bases - Cadastro'!A:C,3,0)) | AR41: =_xlfn.IFNA(VLOOKUP(AO41,'Bases - Cadastro'!$A$37:$B$62,2,0),"")
... L66: =IF(G66="","",VLOOKUP($AN$5,'Bases - Cadastro'!A:C,3,0)) | AR66: =_xlfn.IFNA(VLOOKUP(AO66,'Bases - Cadastro'!$A$37:$B$62,2,0),"")
B67: TOTAL | AU67: =SUM(AU29:BA66) -> 1384.31
C69: Solicitante | U69: Aprovador
C70: DATA | H70: Nome | U70: DATA | W70: Nome
D73: Resumo Contábil | P73: Conta Contábil | V73: =SUM(V74:Z85) -> 0 | AD73: OBSERVAÇÕES
B74: 1 | D74: ='Bases - Cadastro'!A38 -> PR50050001 - Material uso e consumo PROADI SUS | P74: ='Bases - Cadastro'!D38 -> 263020 Reembolso de Material de Uso e Consumo PROADI SUS | V74: =SUMIF($AR$29:$AT$66,P74,$AU$29:$BA$66) -> 0
B75: 2 | D75: ='Bases - Cadastro'!A39 -> PR50060002 - Refeições e Lanches PROADI SUS | P75: ='Bases - Cadastro'!D39 -> 263018 Reembolso de Refeições e Lanches PROADI SUS | V75: =SUMIF($AR$29:$AT$66,P75,$AU$29:$BA$66) -> 0
B76: 3 | D76: ='Bases - Cadastro'!A40 -> PR50060003 - Condução e Transporte PROADI SUS | P76: ='Bases - Cadastro'!D40 -> 263962 Reembolso de Condução e Transporte PROADI SUS | V76: =SUMIF($AR$29:$AT$66,P76,$AU$29:$BA$66) -> 0
B77: 4 | D77: ='Bases - Cadastro'!A41 -> PR50060004 - Passagens Aereas PROADI SUS | P77: ='Bases - Cadastro'!D41 -> 263021 Reembolso de Passagem Aérea PROADI SUS | V77: =SUMIF($AR$29:$AT$66,P77,$AU$29:$BA$66) -> 0
B78: 5 | D78: ='Bases - Cadastro'!A42 -> PR50060005 - Hospedagem PROADI SUS | P78: ='Bases - Cadastro'!D42 -> 263022 Reembolso de Hospedagem PROADI SUS | V78: =SUMIF($AR$29:$AT$66,P78,$AU$29:$BA$66) -> 0
B79: 6 | D79: ='Bases - Cadastro'!A43 -> PR50060006 - Taxas de Viagens, Eventos e Congressos PROADI SUS | P79: ='Bases - Cadastro'!D43 -> 263023 Reembolso de Inscrições de Eventos PROADI SUS | V79: =SUMIF($AR$29:$AT$66,P79,$AU$29:$BA$66) -> 0
B80: 7 | D80: ='Bases - Cadastro'!A44 -> PR50090003 - Custas de cartório PROADI SUS | P80: ='Bases - Cadastro'!D44 -> 263017 Reembolso de Cartório PROADI SUS | V80: =SUMIF($AR$29:$AT$66,P80,$AU$29:$BA$66) -> 0
B81: 8 | D81: ='Bases - Cadastro'!A45 -> PR50090005 - Correios e Malotes PROADI SUS | P81: ='Bases - Cadastro'!D45 -> 263016 Reembolso de Correios PROADI SUS | V81: =SUMIF($AR$29:$AT$66,P81,$AU$29:$BA$66) -> 0
...

Sheet 210815 - Regula Mais
B1: RELATÓRIO DESPESAS - PROADI SUS
B5: Solicitante: | Z5: BP | AJ5: Projeto: | AN5: 210815 PROADI - Projeto Regula Mais Brasil
B7: Atividade:
B9: Período: | N9: à | AG9: EAP - Atividade
B11: Local | Região:
D14: Caixa | BP | I14: Adiantamento de viagem | S14: Reembolso Conta Corrente | AI14: Cartão de Credito Corporativo
C17: DADOS BANCÁRIOS: | S17: (Caso Banco não esteja cadastrado)
B19: Número / Banco | U19: Agência: | AH19: - | AN19: Conta Corrente: | AS19: -
B21: GASTOS REALIZADOS | AN21: Reembolsos
B22: Valor Adiantado | Q22: Valor utilizado | AA22: Saldo | AN22: Valor
B23: 0 | Q23: =AU67 -> 1384.31 | AA23: 0 | AN23: =AU67 -> 1384.31
B25: Comprovante de Despesas
B27: DATA | G27: CENTRO DE CUSTO | L27: PROJETO | Q27: Nº NF | U27: Fornecedor | AA27: Descrição | AO27: CLASSIFICAÇÃO | AR27: CÓD. | AU27: VALOR R$
AO28: DESPESA | AR28: DESP.
B29: 23/08/21 | G29: 210807 | L29: =IF(G29="","",VLOOKUP($AN$5,'Bases - Cadastro'!A:C,3,0)) -> #N/A | U29: Cia Vip | AA29: Hospedagem Hotel Melia - 23 a 26/08/21 - XXXXX | AO29: Viagens e Estadias PROADI SUS | AR29: =_xlfn.IFNA(VLOOKUP(AO29,'Bases - Cadastro'!$A$37:$B$62,2,0),"") | AU29: 1384.31
L30: =IF(G30="","",VLOOKUP($AN$5,'Bases - Cadastro'!A:C,3,0)) | AR30: =_xlfn.IFNA(VLOOKUP(AO30,'Bases - Cadastro'!$A$37:$B$62,2,0),"")
L31: =IF(G31="","",VLOOKUP($AN$5,'Bases - Cadastro'!A:C,3,0)) | AR31: =_xlfn.IFNA(VLOOKUP(AO31,'Bases - Cadastro'!$A$37:$B$62,2,0),"")
L32: =IF(G32="","",VLOOKUP($AN$5,'Bases - Cadastro'!A:C,3,0)) | AR32: =_xlfn.IFNA(VLOOKUP(AO32,'Bases - Cadastro'!$A$37:$B$62,2,0),"")
L33: =IF(G33="","",VLOOKUP($AN$5,'Bases - Cadastro'!A:C,3,0)) | AR33: =_xlfn.IFNA(VLOOKUP(AO33,'Bases - Cadastro'!$A$37:$B$62,2,0),"")
L34: =IF(G34="","",VLOOKUP($AN$5,'Bases - Cadastro'!A:C,3,0)) | AR34: =_xlfn.IFNA(VLOOKUP(AO34,'Bases - Cadastro'!$A$37:$B$62,2,0),"")
L35: =IF(G35="","",VLOOKUP($AN$5,'Bases - Cadastro'!A:C,3,0)) | AR35: =_xlfn.IFNA(VLOOKUP(AO35,'Bases - Cadastro'!$A$37:$B$62,2,0),"")
L36: =IF(G36="","",VLOOKUP($AN$5,'Bases - Cadastro'!A:C,3,0)) | AR36: =_xlfn.IFNA(VLOOKUP(AO36,'Bases - Cadastro'!$A$37:$B$62,2,0),"")
L37: =IF(G37="","",VLOOKUP($AN$5,'Bases - Cadastro'!A:C,3,0)) | AR37: =_xlfn.IFNA(VLOOKUP(AO37,'Bases - Cadastro'!$A$37:$B$62,2,0),"")
L38: =IF(G38="","",VLOOKUP($AN$5,'Bases - Cadastro'!A:C,3,0)) | AR38: =_xlfn.IFNA(VLOOKUP(AO38,'Bases - Cadastro'!$A$37:$B$62,2,0),"")
L39: =IF(G39="","",VLOOKUP($AN$5,'Bases - Cadastro'!A:C,3,0)) | AR39: =_xlfn.IFNA(VLOOKUP(AO39,'Bases - Cadastro'!$A$37:$B$62,2,0),"")
L40: =IF(G40="","",VLOOKUP($AN$5,'Bases - Cadastro'!A:C,3,0)) | AR40: =_xlfn.IFNA(VLOOKUP(AO40,'Bases - Cadastro'!$A$37:$B$62,2,0),"")
L41: =IF(G41="","",VLOOKUP($AN$5,'Bases - Cadastro'!A:C,3,0)) | AR41: =_xlfn.IFNA(VLOOKUP(AO41,'Bases - Cadastro'!$A$37:$B$62,2,0),"")
... L66: =IF(G66="","",VLOOKUP($AN$5,'Bases - Cadastro'!A:C,3,0)) | AR66: =_xlfn.IFNA(VLOOKUP(AO66,'Bases - Cadastro'!$A$37:$B$62,2,0),"")
B67: TOTAL | AU67: =SUM(AU29:BA66) -> 1384.31
C69: Solicitante | U69: Aprovador
C70: DATA | H70: Nome | U70: DATA | W70: Nome
D73: Resumo Contábil | P73: Conta Contábil | V73: =SUM(V74:Z85) -> 0 | AD73: OBSERVAÇÕES
B74: 1 | D74: ='Bases - Cadastro'!A38 -> PR50050001 - Material uso e consumo PROADI SUS | P74: ='Bases - Cadastro'!D38 -> 263020 Reembolso de Material de Uso e Consumo PROADI SUS | V74: =SUMIF($AR$29:$AT$66,P74,$AU$29:$BA$66) -> 0
B75: 2 | D75: ='Bases - Cadastro'!A39 -> PR50060002 - Refeições e Lanches PROADI SUS | P75: ='Bases - Cadastro'!D39 -> 263018 Reembolso de Refeições e Lanches PROADI SUS | V75: =SUMIF($AR$29:$AT$66,P75,$AU$29:$BA$66) -> 0
B76: 3 | D76: ='Bases - Cadastro'!A40 -> PR50060003 - Condução e Transporte PROADI SUS | P76: ='Bases - Cadastro'!D40 -> 263962 Reembolso de Condução e Transporte PROADI SUS | V76: =SUMIF($AR$29:$AT$66,P76,$AU$29:$BA$66) -> 0
B77: 4 | D77: ='Bases - Cadastro'!A41 -> PR50060004 - Passagens Aereas PROADI SUS | P77: ='Bases - Cadastro'!D41 -> 263021 Reembolso de Passagem Aérea PROADI SUS | V77: =SUMIF($AR$29:$AT$66,P77,$AU$29:$BA$66) -> 0
B78: 5 | D78: ='Bases - Cadastro'!A42 -> PR50060005 - Hospedagem PROADI SUS | P78: ='Bases - Cadastro'!D42 -> 263022 Reembolso de Hospedagem PROADI SUS | V78: =SUMIF($AR$29:$AT$66,P78,$AU$29:$BA$66) -> 0
B79: 6 | D79: ='Bases - Cadastro'!A43 -> PR50060006 - Taxas de Viagens, Eventos e Congressos PROADI SUS | P79: ='Bases - Cadastro'!D43 -> 263023 Reembolso de Inscrições de Eventos PROADI SUS | V79: =SUMIF($AR$29:$AT$66,P79,$AU$29:$BA$66) -> 0
B80: 7 | D80: ='Bases - Cadastro'!A44 -> PR50090003 - Custas de cartório PROADI SUS | P80: ='Bases - Cadastro'!D44 -> 263017 Reembolso de Cartório PROADI SUS | V80: =SUMIF($AR$29:$AT$66,P80,$AU$29:$BA$66) -> 0
B81: 8 | D81: ='Bases - Cadastro'!A45 -> PR50090005 - Correios e Malotes PROADI SUS | P81: ='Bases - Cadastro'!D45 -> 263016 Reembolso de Correios PROADI SUS | V81: =SUMIF($AR$29:$AT$66,P81,$AU$29:$BA$66) -> 0
...

Sheet 210816 - Saude
B1: RELATÓRIO DESPESAS - PROADI SUS
B5: Solicitante: | Z5: BP | AJ5: Projeto: | AN5: 210816 PROADI - Projeto Saude em Nossas Mãos
B7: Atividade:
B9: Período: | N9: à | AG9: EAP - Atividade
B11: Local | Região:
D14: Caixa | BP | I14: Adiantamento de viagem | S14: Reembolso Conta Corrente | AI14: Cartão de Credito Corporativo
C17: DADOS BANCÁRIOS: | S17: (Caso Banco não esteja cadastrado)
B19: Número / Banco | U19: Agência: | AH19: - | AN19: Conta Corrente: | AS19: -
B21: GASTOS REALIZADOS | AN21: Reembolsos
B22: Valor Adiantado | Q22: Valor utilizado | AA22: Saldo | AN22: Valor
B23: 0 | Q23: =AU67 -> 1384.31 | AA23: 0 | AN23: =AU67 -> 1384.31
B25: Comprovante de Despesas
B27: DATA | G27: CENTRO DE CUSTO | L27: PROJETO | Q27: Nº NF | U27: Fornecedor | AA27: Descrição | AO27: CLASSIFICAÇÃO | AR27: CÓD. | AU27: VALOR R$
AO28: DESPESA | AR28: DESP.
B29: 23/08/21 | G29: 210807 | L29: =IF(G29="","",VLOOKUP($AN$5,'Bases - Cadastro'!A:C,3,0)) -> #N/A | U29: Cia Vip | AA29: Hospedagem Hotel Melia - 23 a 26/08/21 - XXXXX | AO29: Viagens e Estadias PROADI SUS | AR29: =_xlfn.IFNA(VLOOKUP(AO29,'Bases - Cadastro'!$A$37:$B$62,2,0),"") | AU29: 1384.31
L30: =IF(G30="","",VLOOKUP($AN$5,'Bases - Cadastro'!A:C,3,0)) | AR30: =_xlfn.IFNA(VLOOKUP(AO30,'Bases - Cadastro'!$A$37:$B$62,2,0),"")
L31: =IF(G31="","",VLOOKUP($AN$5,'Bases - Cadastro'!A:C,3,0)) | AR31: =_xlfn.IFNA(VLOOKUP(AO31,'Bases - Cadastro'!$A$37:$B$62,2,0),"")
L32: =IF(G32="","",VLOOKUP($AN$5,'Bases - Cadastro'!A:C,3,0)) | AR32: =_xlfn.IFNA(VLOOKUP(AO32,'Bases - Cadastro'!$A$37:$B$62,2,0),"")
L33: =IF(G33="","",VLOOKUP($AN$5,'Bases - Cadastro'!A:C,3,0)) | AR33: =_xlfn.IFNA(VLOOKUP(AO33,'Bases - Cadastro'!$A$37:$B$62,2,0),"")
L34: =IF(G34="","",VLOOKUP($AN$5,'Bases - Cadastro'!A:C,3,0)) | AR34: =_xlfn.IFNA(VLOOKUP(AO34,'Bases - Cadastro'!$A$37:$B$62,2,0),"")
L35: =IF(G35="","",VLOOKUP($AN$5,'Bases - Cadastro'!A:C,3,0)) | AR35: =_xlfn.IFNA(VLOOKUP(AO35,'Bases - Cadastro'!$A$37:$B$62,2,0),"")
L36: =IF(G36="","",VLOOKUP($AN$5,'Bases - Cadastro'!A:C,3,0)) | AR36: =_xlfn.IFNA(VLOOKUP(AO36,'Bases - Cadastro'!$A$37:$B$62,2,0),"")
L37: =IF(G37="","",VLOOKUP($AN$5,'Bases - Cadastro'!A:C,3,0)) | AR37: =_xlfn.IFNA(VLOOKUP(AO37,'Bases - Cadastro'!$A$37:$B$62,2,0),"")
L38: =IF(G38="","",VLOOKUP($AN$5,'Bases - Cadastro'!A:C,3,0)) | AR38: =_xlfn.IFNA(VLOOKUP(AO38,'Bases - Cadastro'!$A$37:$B$62,2,0),"")
L39: =IF(G39="","",VLOOKUP($AN$5,'Bases - Cadastro'!A:C,3,0)) | AR39: =_xlfn.IFNA(VLOOKUP(AO39,'Bases - Cadastro'!$A$37:$B$62,2,0),"")
L40: =IF(G40="","",VLOOKUP($AN$5,'Bases - Cadastro'!A:C,3,0)) | AR40: =_xlfn.IFNA(VLOOKUP(AO40,'Bases - Cadastro'!$A$37:$B$62,2,0),"")
L41: =IF(G41="","",VLOOKUP($AN$5,'Bases - Cadastro'!A:C,3,0)) | AR41: =_xlfn.IFNA(VLOOKUP(AO41,'Bases - Cadastro'!$A$37:$B$62,2,0),"")
... L66: =IF(G66="","",VLOOKUP($AN$5,'Bases - Cadastro'!A:C,3,0)) | AR66: =_xlfn.IFNA(VLOOKUP(AO66,'Bases - Cadastro'!$A$37:$B$62,2,0),"")
B67: TOTAL | AU67: =SUM(AU29:BA66) -> 1384.31
C69: Solicitante | U69: Aprovador
C70: DATA | H70: Nome | U70: DATA | W70: Nome
D73: Resumo Contábil | P73: Conta Contábil | V73: =SUM(V74:Z85) -> 0 | AD73: OBSERVAÇÕES
B74: 1 | D74: ='Bases - Cadastro'!A38 -> PR50050001 - Material uso e consumo PROADI SUS | P74: ='Bases - Cadastro'!D38 -> 263020 Reembolso de Material de Uso e Consumo PROADI SUS | V74: =SUMIF($AR$29:$AT$66,P74,$AU$29:$BA$66) -> 0
B75: 2 | D75: ='Bases - Cadastro'!A39 -> PR50060002 - Refeições e Lanches PROADI SUS | P75: ='Bases - Cadastro'!D39 -> 263018 Reembolso de Refeições e Lanches PROADI SUS | V75: =SUMIF($AR$29:$AT$66,P75,$AU$29:$BA$66) -> 0
B76: 3 | D76: ='Bases - Cadastro'!A40 -> PR50060003 - Condução e Transporte PROADI SUS | P76: ='Bases - Cadastro'!D40 -> 263962 Reembolso de Condução e Transporte PROADI SUS | V76: =SUMIF($AR$29:$AT$66,P76,$AU$29:$BA$66) -> 0
B77: 4 | D77: ='Bases - Cadastro'!A41 -> PR50060004 - Passagens Aereas PROADI SUS | P77: ='Bases - Cadastro'!D41 -> 263021 Reembolso de Passagem Aérea PROADI SUS | V77: =SUMIF($AR$29:$AT$66,P77,$AU$29:$BA$66) -> 0
B78: 5 | D78: ='Bases - Cadastro'!A42 -> PR50060005 - Hospedagem PROADI SUS | P78: ='Bases - Cadastro'!D42 -> 263022 Reembolso de Hospedagem PROADI SUS | V78: =SUMIF($AR$29:$AT$66,P78,$AU$29:$BA$66) -> 0
B79: 6 | D79: ='Bases - Cadastro'!A43 -> PR50060006 - Taxas de Viagens, Eventos e Congressos PROADI SUS | P79: ='Bases - Cadastro'!D43 -> 263023 Reembolso de Inscrições de Eventos PROADI SUS | V79: =SUMIF($AR$29:$AT$66,P79,$AU$29:$BA$66) -> 0
B80: 7 | D80: ='Bases - Cadastro'!A44 -> PR50090003 - Custas de cartório PROADI SUS | P80: ='Bases - Cadastro'!D44 -> 263017 Reembolso de Cartório PROADI SUS | V80: =SUMIF($AR$29:$AT$66,P80,$AU$29:$BA$66) -> 0
B81: 8 | D81: ='Bases - Cadastro'!A45 -> PR50090005 - Correios e Malotes PROADI SUS | P81: ='Bases - Cadastro'!D45 -> 263016 Reembolso de Correios PROADI SUS | V81: =SUMIF($AR$29:$AT$66,P81,$AU$29:$BA$66) -> 0
...

Sheet 210818 - Rede
B1: RELATÓRIO DESPESAS - PROADI SUS
B5: Solicitante: | Z5: BP | AJ5: Projeto: | AN5: 210818 PROADI - Projeto Rede Colaborativa
B7: Atividade:
B9: Período: | N9: à | AG9: EAP - Atividade
B11: Local | Região:
D14: Caixa | BP | I14: Adiantamento de viagem | S14: Reembolso Conta Corrente | AI14: Cartão de Credito Corporativo
C17: DADOS BANCÁRIOS: | S17: (Caso Banco não esteja cadastrado)
B19: Número / Banco | U19: Agência: | AH19: - | AN19: Conta Corrente: | AS19: -
B21: GASTOS REALIZADOS | AN21: Reembolsos
B22: Valor Adiantado | Q22: Valor utilizado | AA22: Saldo | AN22: Valor
B23: 0 | Q23: =AU67 -> 1384.31 | AA23: 0 | AN23: =AU67 -> 1384.31
B25: Comprovante de Despesas
B27: DATA | G27: CENTRO DE CUSTO | L27: PROJETO | Q27: Nº NF | U27: Fornecedor | AA27: Descrição | AO27: CLASSIFICAÇÃO | AR27: CÓD. | AU27: VALOR R$
AO28: DESPESA | AR28: DESP.
B29: 23/08/21 | G29: 210807 | L29: =IF(G29="","",VLOOKUP($AN$5,'Bases - Cadastro'!A:C,3,0)) -> #N/A | U29: Cia Vip | AA29: Hospedagem Hotel Melia - 23 a 26/08/21 - XXXXX | AO29: Viagens e Estadias PROADI SUS | AR29: =_xlfn.IFNA(VLOOKUP(AO29,'Bases - Cadastro'!$A$37:$B$62,2,0),"") | AU29: 1384.31
L30: =IF(G30="","",VLOOKUP($AN$5,'Bases - Cadastro'!A:C,3,0)) | AR30: =_xlfn.IFNA(VLOOKUP(AO30,'Bases - Cadastro'!$A$37:$B$62,2,0),"")
L31: =IF(G31="","",VLOOKUP($AN$5,'Bases - Cadastro'!A:C,3,0)) | AR31: =_xlfn.IFNA(VLOOKUP(AO31,'Bases - Cadastro'!$A$37:$B$62,2,0),"")
L32: =IF(G32="","",VLOOKUP($AN$5,'Bases - Cadastro'!A:C,3,0)) | AR32: =_xlfn.IFNA(VLOOKUP(AO32,'Bases - Cadastro'!$A$37:$B$62,2,0),"")
L33: =IF(G33="","",VLOOKUP($AN$5,'Bases - Cadastro'!A:C,3,0)) | AR33: =_xlfn.IFNA(VLOOKUP(AO33,'Bases - Cadastro'!$A$37:$B$62,2,0),"")
L34: =IF(G34="","",VLOOKUP($AN$5,'Bases - Cadastro'!A:C,3,0)) | AR34: =_xlfn.IFNA(VLOOKUP(AO34,'Bases - Cadastro'!$A$37:$B$62,2,0),"")
L35: =IF(G35="","",VLOOKUP($AN$5,'Bases - Cadastro'!A:C,3,0)) | AR35: =_xlfn.IFNA(VLOOKUP(AO35,'Bases - Cadastro'!$A$37:$B$62,2,0),"")
L36: =IF(G36="","",VLOOKUP($AN$5,'Bases - Cadastro'!A:C,3,0)) | AR36: =_xlfn.IFNA(VLOOKUP(AO36,'Bases - Cadastro'!$A$37:$B$62,2,0),"")
L37: =IF(G37="","",VLOOKUP($AN$5,'Bases - Cadastro'!A:C,3,0)) | AR37: =_xlfn.IFNA(VLOOKUP(AO37,'Bases - Cadastro'!$A$37:$B$62,2,0),"")
L38: =IF(G38="","",VLOOKUP($AN$5,'Bases - Cadastro'!A:C,3,0)) | AR38: =_xlfn.IFNA(VLOOKUP(AO38,'Bases - Cadastro'!$A$37:$B$62,2,0),"")
L39: =IF(G39="","",VLOOKUP($AN$5,'Bases - Cadastro'!A:C,3,0)) | AR39: =_xlfn.IFNA(VLOOKUP(AO39,'Bases - Cadastro'!$A$37:$B$62,2,0),"")
L40: =IF(G40="","",VLOOKUP($AN$5,'Bases - Cadastro'!A:C,3,0)) | AR40: =_xlfn.IFNA(VLOOKUP(AO40,'Bases - Cadastro'!$A$37:$B$62,2,0),"")
L41: =IF(G41="","",VLOOKUP($AN$5,'Bases - Cadastro'!A:C,3,0)) | AR41: =_xlfn.IFNA(VLOOKUP(AO41,'Bases - Cadastro'!$A$37:$B$62,2,0),"")
... L66: =IF(G66="","",VLOOKUP($AN$5,'Bases - Cadastro'!A:C,3,0)) | AR66: =_xlfn.IFNA(VLOOKUP(AO66,'Bases - Cadastro'!$A$37:$B$62,2,0),"")
B67: TOTAL | AU67: =SUM(AU29:BA66) -> 1384.31
C69: Solicitante | U69: Aprovador
C70: DATA | H70: Nome | U70: DATA | W70: Nome
D73: Resumo Contábil | P73: Conta Contábil | V73: =SUM(V74:Z85) -> 0 | AD73: OBSERVAÇÕES
B74: 1 | D74: ='Bases - Cadastro'!A38 -> PR50050001 - Material uso e consumo PROADI SUS | P74: ='Bases - Cadastro'!D38 -> 263020 Reembolso de Material de Uso e Consumo PROADI SUS | V74: =SUMIF($AR$29:$AT$66,P74,$AU$29:$BA$66) -> 0
B75: 2 | D75: ='Bases - Cadastro'!A39 -> PR50060002 - Refeições e Lanches PROADI SUS | P75: ='Bases - Cadastro'!D39 -> 263018 Reembolso de Refeições e Lanches PROADI SUS | V75: =SUMIF($AR$29:$AT$66,P75,$AU$29:$BA$66) -> 0
B76: 3 | D76: ='Bases - Cadastro'!A40 -> PR50060003 - Condução e Transporte PROADI SUS | P76: ='Bases - Cadastro'!D40 -> 263962 Reembolso de Condução e Transporte PROADI SUS | V76: =SUMIF($AR$29:$AT$66,P76,$AU$29:$BA$66) -> 0
B77: 4 | D77: ='Bases - Cadastro'!A41 -> PR50060004 - Passagens Aereas PROADI SUS | P77: ='Bases - Cadastro'!D41 -> 263021 Reembolso de Passagem Aérea PROADI SUS | V77: =SUMIF($AR$29:$AT$66,P77,$AU$29:$BA$66) -> 0
B78: 5 | D78: ='Bases - Cadastro'!A42 -> PR50060005 - Hospedagem PROADI SUS | P78: ='Bases - Cadastro'!D42 -> 263022 Reembolso de Hospedagem PROADI SUS | V78: =SUMIF($AR$29:$AT$66,P78,$AU$29:$BA$66) -> 0
B79: 6 | D79: ='Bases - Cadastro'!A43 -> PR50060006 - Taxas de Viagens, Eventos e Congressos PROADI SUS | P79: ='Bases - Cadastro'!D43 -> 263023 Reembolso de Inscrições de Eventos PROADI SUS | V79: =SUMIF($AR$29:$AT$66,P79,$AU$29:$BA$66) -> 0
B80: 7 | D80: ='Bases - Cadastro'!A44 -> PR50090003 - Custas de cartório PROADI SUS | P80: ='Bases - Cadastro'!D44 -> 263017 Reembolso de Cartório PROADI SUS | V80: =SUMIF($AR$29:$AT$66,P80,$AU$29:$BA$66) -> 0
B81: 8 | D81: ='Bases - Cadastro'!A45 -> PR50090005 - Correios e Malotes PROADI SUS | P81: ='Bases - Cadastro'!D45 -> 263016 Reembolso de Correios PROADI SUS | V81: =SUMIF($AR$29:$AT$66,P81,$AU$29:$BA$66) -> 0
...
